Traceback (most recent call last):
  File "C:\Users\acer\AppData\Roaming\Python\Python312\site-packages\jupyter_cache\executors\utils.py", line 58, in single_nb_execution
    executenb(
  File "C:\Users\acer\AppData\Roaming\Python\Python312\site-packages\nbclient\client.py", line 1319, in execute
    return NotebookClient(nb=nb, resources=resources, km=km, **kwargs).execute()
           ^^^^^^^^^^^^^^^^^^^^^^^^^^^^^^^^^^^^^^^^^^^^^^^^^^^^^^^^^^^^^^^^^^^^^
  File "C:\Users\acer\AppData\Roaming\Python\Python312\site-packages\jupyter_core\utils\__init__.py", line 165, in wrapped
    return loop.run_until_complete(inner)
           ^^^^^^^^^^^^^^^^^^^^^^^^^^^^^^
  File "C:\Program Files\Python312\Lib\asyncio\base_events.py", line 685, in run_until_complete
    return future.result()
           ^^^^^^^^^^^^^^^
  File "C:\Users\acer\AppData\Roaming\Python\Python312\site-packages\nbclient\client.py", line 709, in async_execute
    await self.async_execute_cell(
  File "C:\Users\acer\AppData\Roaming\Python\Python312\site-packages\nbclient\client.py", line 1062, in async_execute_cell
    await self._check_raise_for_error(cell, cell_index, exec_reply)
  File "C:\Users\acer\AppData\Roaming\Python\Python312\site-packages\nbclient\client.py", line 918, in _check_raise_for_error
    raise CellExecutionError.from_cell_and_msg(cell, exec_reply_content)
nbclient.exceptions.CellExecutionError: An error occurred while executing the following cell:
------------------
import pandas as pd
import matplotlib.pyplot as plt
import seaborn as sns

# Muat dataset
try:
    df = pd.read_csv('Maternal Health Risk Data Set.csv')
except FileNotFoundError:
    print("Error: 'Maternal Health Risk Data Set.csv' not found. Please make sure the file is in the correct directory.")
    exit()

print("--- 1. Tinjauan Awal Data ---")
print("5 baris pertama:")
print(df.head())
print("\n5 baris terakhir:")
print(df.tail())

------------------

----- stdout -----
Error: 'Maternal Health Risk Data Set.csv' not found. Please make sure the file is in the correct directory.
--- 1. Tinjauan Awal Data ---
5 baris pertama:
------------------

[1;31m---------------------------------------------------------------------------[0m
[1;31mNameError[0m                                 Traceback (most recent call last)
Cell [1;32mIn[1], line 14[0m
[0;32m     12[0m [38;5;28mprint[39m([38;5;124m"[39m[38;5;124m--- 1. Tinjauan Awal Data ---[39m[38;5;124m"[39m)
[0;32m     13[0m [38;5;28mprint[39m([38;5;124m"[39m[38;5;124m5 baris pertama:[39m[38;5;124m"[39m)
[1;32m---> 14[0m [38;5;28mprint[39m([43mdf[49m[38;5;241m.[39mhead())
[0;32m     15[0m [38;5;28mprint[39m([38;5;124m"[39m[38;5;130;01m\n[39;00m[38;5;124m5 baris terakhir:[39m[38;5;124m"[39m)
[0;32m     16[0m [38;5;28mprint[39m(df[38;5;241m.[39mtail())

[1;31mNameError[0m: name 'df' is not defined

